Workbook

Sheet diabetes
A1: Pregnancies | B1: Glucose | C1: BloodPressure | D1: SkinThickness | E1: Insulin | F1: BMI | G1: DiabetesPedigreeFunction | H1: Age | I1: Outcome
A2: 6 | B2: 148 | C2: 72 | D2: 35 | E2: 0 | F2: 33.6 | G2: 0.627 | H2: 50 | I2: 1
A3: 1 | B3: 85 | C3: 66 | D3: 29 | E3: 0 | F3: 26.6 | G3: 0.351 | H3: 31 | I3: 0
A4: 8 | B4: 183 | C4: 64 | D4: 0 | E4: 0 | F4: 23.3 | G4: 0.672 | H4: 32 | I4: 1
A5: 1 | B5: 89 | C5: 66 | D5: 23 | E5: 94 | F5: 28.1 | G5: 0.167 | H5: 21 | I5: 0
A6: 0 | B6: 137 | C6: 40 | D6: 35 | E6: 168 | F6: 43.1 | G6: 2.288 | H6: 33 | I6: 1
A7: 5 | B7: 116 | C7: 74 | D7: 0 | E7: 0 | F7: 25.6 | G7: 0.201 | H7: 30 | I7: 0
A8: 3 | B8: 78 | C8: 50 | D8: 32 | E8: 88 | F8: 31 | G8: 0.248 | H8: 26 | I8: 1
A9: 10 | B9: 115 | C9: 0 | D9: 0 | E9: 0 | F9: 35.3 | G9: 0.134 | H9: 29 | I9: 0
A10: 2 | B10: 197 | C10: 70 | D10: 45 | E10: 543 | F10: 30.5 | G10: 0.158 | H10: 53 | I10: 1
A11: 8 | B11: 125 | C11: 96 | D11: 0 | E11: 0 | F11: 0 | G11: 0.232 | H11: 54 | I11: 1
A12: 4 | B12: 110 | C12: 92 | D12: 0 | E12: 0 | F12: 37.6 | G12: 0.191 | H12: 30 | I12: 0
A13: 10 | B13: 168 | C13: 74 | D13: 0 | E13: 0 | F13: 38 | G13: 0.537 | H13: 34 | I13: 1
... A769: 1 | B769: 93 | C769: 70 | D769: 31 | E769: 0 | F769: 30.4 | G769: 0.315 | H769: 23 | I769: 0

Sheet CLEAN DATA 
A1: Pregnancies | B1: Glucose | C1: BloodPressure | D1: BMI | E1: DiabetesPedigreeFunction | F1: Age | G1: Outcome | H1: Glucose_NonDiabetic | I1: Glucose_Diabetic
A2: 6 | B2: 148 | C2: 72 | D2: 33.6 | E2: 0.627 | F2: 50 | G2: 1 | I2: 148
A3: 1 | B3: 85 | C3: 66 | D3: 26.6 | E3: 0.351 | F3: 31 | G3: 0 | H3: 85
A4: 8 | B4: 183 | C4: 64 | D4: 23.3 | E4: 0.672 | F4: 32 | G4: 1 | I4: 183
A5: 1 | B5: 89 | C5: 66 | D5: 28.1 | E5: 0.167 | F5: 21 | G5: 0 | H5: 89
A6: 0 | B6: 137 | C6: 40 | D6: 43.1 | E6: 2.288 | F6: 33 | G6: 1 | I6: 137
A7: 5 | B7: 116 | C7: 74 | D7: 25.6 | E7: 0.201 | F7: 30 | G7: 0 | H7: 116
A8: 3 | B8: 78 | C8: 50 | D8: 31 | E8: 0.248 | F8: 26 | G8: 1 | I8: 78
A9: 10 | B9: 115 | C9: 72 | D9: 35.3 | E9: 0.134 | F9: 29 | G9: 0 | H9: 115
A10: 2 | B10: 197 | C10: 70 | D10: 30.5 | E10: 0.158 | F10: 53 | G10: 1 | I10: 197
A11: 8 | B11: 125 | C11: 96 | D11: 32 | E11: 0.232 | F11: 54 | G11: 1 | I11: 125
A12: 4 | B12: 110 | C12: 92 | D12: 37.6 | E12: 0.191 | F12: 30 | G12: 0 | H12: 110
A13: 10 | B13: 168 | C13: 74 | D13: 38 | E13: 0.537 | F13: 34 | G13: 1 | I13: 168
A14: 10 | B14: 139 | C14: 80 | D14: 27.1 | E14: 1.441 | F14: 57 | G14: 0 | H14: 139
A15: 1 | B15: 189 | C15: 60 | D15: 30.1 | E15: 0.398 | F15: 59 | G15: 1 | I15: 189
A16: 5 | B16: 166 | C16: 72 | D16: 25.8 | E16: 0.587 | F16: 51 | G16: 1 | I16: 166
A17: 7 | B17: 100 | C17: 72 | D17: 30 | E17: 0.484 | F17: 32 | G17: 1 | I17: 100
A18: 0 | B18: 118 | C18: 84 | D18: 45.8 | E18: 0.551 | F18: 31 | G18: 1 | I18: 118
A19: 7 | B19: 107 | C19: 74 | D19: 29.6 | E19: 0.254 | F19: 31 | G19: 1 | I19: 107
A20: 1 | B20: 103 | C20: 30 | D20: 43.3 | E20: 0.183 | F20: 33 | G20: 0 | H20: 103
A21: 1 | B21: 115 | C21: 70 | D21: 34.6 | E21: 0.529 | F21: 32 | G21: 1 | I21: 115
A22: 3 | B22: 126 | C22: 88 | D22: 39.3 | E22: 0.704 | F22: 27 | G22: 0 | H22: 126
A23: 8 | B23: 99 | C23: 84 | D23: 35.4 | E23: 0.388 | F23: 50 | G23: 0 | H23: 99
A24: 7 | B24: 196 | C24: 90 | D24: 39.8 | E24: 0.451 | F24: 41 | G24: 1 | I24: 196
A25: 9 | B25: 119 | C25: 80 | D25: 29 | E25: 0.263 | F25: 29 | G25: 1 | I25: 119
A26: 11 | B26: 143 | C26: 94 | D26: 36.6 | E26: 0.254 | F26: 51 | G26: 1 | I26: 143
A27: 10 | B27: 125 | C27: 70 | D27: 31.1 | E27: 0.205 | F27: 41 | G27: 1 | I27: 125
A28: 7 | B28: 147 | C28: 76 | D28: 39.4 | E28: 0.257 | F28: 43 | G28: 1 | I28: 147
A29: 1 | B29: 97 | C29: 66 | D29: 23.2 | E29: 0.487 | F29: 22 | G29: 0 | H29: 97
A30: 13 | B30: 145 | C30: 82 | D30: 22.2 | E30: 0.245 | F30: 57 | G30: 0 | H30: 145
A31: 5 | B31: 117 | C31: 92 | D31: 34.1 | E31: 0.337 | F31: 38 | G31: 0 | H31: 117
A32: 5 | B32: 109 | C32: 75 | D32: 36 | E32: 0.546 | F32: 60 | G32: 0 | H32: 109
A33: 3 | B33: 158 | C33: 76 | D33: 31.6 | E33: 0.851 | F33: 28 | G33: 1 | I33: 158
A34: 3 | B34: 88 | C34: 58 | D34: 24.8 | E34: 0.267 | F34: 22 | G34: 0 | H34: 88
A35: 6 | B35: 92 | C35: 92 | D35: 19.9 | E35: 0.188 | F35: 28 | G35: 0 | H35: 92
A36: 10 | B36: 122 | C36: 78 | D36: 27.6 | E36: 0.512 | F36: 45 | G36: 0 | H36: 122
A37: 4 | B37: 103 | C37: 60 | D37: 24 | E37: 0.966 | F37: 33 | G37: 0 | H37: 103
A38: 11 | B38: 138 | C38: 76 | D38: 33.2 | E38: 0.42 | F38: 35 | G38: 0 | H38: 138
A39: 9 | B39: 102 | C39: 76 | D39: 32.9 | E39: 0.665 | F39: 46 | G39: 1 | I39: 102
A40: 2 | B40: 90 | C40: 68 | D40: 38.2 | E40: 0.503 | F40: 27 | G40: 1 | I40: 90
...

Sheet P- VALUE AND CORRELATION
C4: T-Test p-value (Glucose) | D4: {=_xlfn.T.TEST(IF('CLEAN DATA '!$G$2:$G$769=0,'CLEAN DATA '!$B$2:$B$769),IF('CLEAN DATA '!$G$2:$G$769=1,'CLEAN DATA '!$B$2:$B$769),2,3)} -> 3.5421486e-41
C7: CORRELATION WITH OUTCOME
C9: VARIABLE | D9: FORMULA | F9: STRENGHT
C10: GLUCOSE | D10: =CORREL('CLEAN DATA '!B:B,'CLEAN DATA '!G:G) -> 0.4927824 | F10: STRONG
C12: BLOOD PRESSURE | D12: =CORREL('CLEAN DATA '!C:C,'CLEAN DATA '!G:G) -> 0.16572291 | F12: MODERATE
C14: BMI | D14: =CORREL('CLEAN DATA '!D:D,'CLEAN DATA '!G:G) -> 0.31224903 | F14: WEAK - MODERATE
C16: AGE | D16: =CORREL('CLEAN DATA '!F:F,'CLEAN DATA '!G:G) -> 0.23835598 | F16: WEAK - MODERATE
C18: PREGNENCIES | D18: =CORREL('CLEAN DATA '!A:A,'CLEAN DATA '!G:G) -> 0.22189815 | F18: WEAK
C20: DIABETES PEDUGREE FUNCTION | D20: =CORREL('CLEAN DATA '!E:E,'CLEAN DATA '!G:G) -> 0.17384407 | F20: MOST- WEAK

Sheet DESCRIPTIVE STATISTIC 
D2: Outcome = 0 (Non-Diabetic) | F2: Outcome = 1 (Diabetic)
C4: MEAN GLUCOSE | D4: =AVERAGEIF('CLEAN DATA '!$G:$G,0,'CLEAN DATA '!B:B) -> 110.682 | F4: =AVERAGEIF('CLEAN DATA '!$G:$G,1,'CLEAN DATA '!B:B) -> 142.1306
C6: MEAN BLOOD PRESSURE | D6: =AVERAGEIF('CLEAN DATA '!G:G,0,'CLEAN DATA '!C:C) -> 70.92 | F6: =AVERAGEIF('CLEAN DATA '!$G:$G,1,'CLEAN DATA '!C:C) -> 75.123134
C8: MEAN BMI | D8: =AVERAGEIF('CLEAN DATA '!G:G,0,'CLEAN DATA '!D:D) -> 30.8802 | F8: =AVERAGEIF('CLEAN DATA '!$G:$G,1,'CLEAN DATA '!D:D) -> 35.381343
C10: MEAN AGE | D10: =AVERAGEIF('CLEAN DATA '!G:G,0,'CLEAN DATA '!F:F) -> 31.19 | F10: =AVERAGEIF('CLEAN DATA '!$G:$G,1,'CLEAN DATA '!F:F) -> 37.067164
C15: MEDIAN GLUCOSE | D15: {=MEDIAN(IF('CLEAN DATA '!$G$2:$G$769=0,'CLEAN DATA '!$B$2:$B$769))} -> 107.5 | F15: {=MEDIAN(IF('CLEAN DATA '!$G$2:$G$769=1,'CLEAN DATA '!$B$2:$B$769))} -> 140
C17: MEDIAN BLOOD PRESSURE | D17: {=MEDIAN(IF('CLEAN DATA '!$G$2:$G$769=0,'CLEAN DATA '!$C$2:$C$769))} -> 72 | F17: {=MEDIAN(IF('CLEAN DATA '!$G$2:$G$769=1,'CLEAN DATA '!$C$2:$C$769))} -> 74
C19: MEDIAN BMI | D19: {=MEDIAN(IF('CLEAN DATA '!$G$2:$G$769=0,'CLEAN DATA '!$D$2:$D$769))} -> 30.4 | F19: {=MEDIAN(IF('CLEAN DATA '!$G$2:$G$769=1,'CLEAN DATA '!$D$2:$D$769))} -> 34.25
C21: MEDIAN AGE | D21: {=MEDIAN(IF('CLEAN DATA '!$G$2:$G$769=0,'CLEAN DATA '!$F$2:$F$769))} -> 27 | F21: {=MEDIAN(IF('CLEAN DATA '!$G$2:$G$769=1,'CLEAN DATA '!$F$2:$F$769))} -> 36
C25: SD GLUCOSE | D25: {=_xlfn.STDEV.S(IF('CLEAN DATA '!$G$2:$G$769=0,'CLEAN DATA '!$B$2:$B$769))} -> 24.707201 | F25: {=_xlfn.STDEV.S(IF('CLEAN DATA '!$G$2:$G$769=1,'CLEAN DATA '!$B$2:$B$769))} -> 29.568839
C27: SD BLOOD PRESSURE | D27: {=_xlfn.STDEV.S(IF('CLEAN DATA '!$G$2:$G$769=0,'CLEAN DATA '!$C$2:$C$769))} -> 11.929385 | F27: {=_xlfn.STDEV.S(IF('CLEAN DATA '!$G$2:$G$769=1,'CLEAN DATA '!$C$2:$C$769))} -> 11.951672
C29: SD BMI | D29: {=_xlfn.STDEV.S(IF('CLEAN DATA '!$G$2:$G$769=0,'CLEAN DATA '!$D$2:$D$769))} -> 6.5030737 | F29: {=_xlfn.STDEV.S(IF('CLEAN DATA '!$G$2:$G$769=1,'CLEAN DATA '!$D$2:$D$769))} -> 6.5967041
C31: SD AGE | D31: {=_xlfn.STDEV.S(IF('CLEAN DATA '!$G$2:$G$769=0,'CLEAN DATA '!$F$2:$F$769))} -> 11.667655 | F31: {=_xlfn.STDEV.S(IF('CLEAN DATA '!$G$2:$G$769=1,'CLEAN DATA '!$F$2:$F$769))} -> 10.968254

Sheet PIVOT TABLE 
C5: Row Labels | D5: Average of BloodPressure | E5: Average of Glucose | F5: Average of BMI | G5: Average of DiabetesPedigreeFunction | H5: Average of Pregnancies | I5: Average of Age
C6: 0 | D6: 70.92 | E6: 110.682 | F6: 30.8802 | G6: 0.429734 | H6: 3.298 | I6: 31.19
C7: 1 | D7: 75.123134 | E7: 142.1306 | F7: 35.381343 | G7: 0.5505 | H7: 4.8656716 | I7: 37.067164
C8: Grand Total | D8: 72.386719 | E8: 121.65625 | F8: 32.450911 | G8: 0.4718763 | H8: 3.8450521 | I8: 33.240885
